# Analysis Fix Summary - October 26, 2025

## Problem Statement
Analysis tasks were failing with "can't subtract offset-naive and offset-aware datetimes" error, preventing analysis results from being produced and displayed.

## Root Cause Analysis
The issue was in `src/app/services/task_execution_service.py` where datetime calculations mixed:
- **Naive datetimes** (created with `datetime.utcnow()`)
- **Timezone-aware datetimes** (created with `datetime.now(timezone.utc)` in other parts of the system)

When Python attempted to calculate `actual_duration` by subtracting these timestamps, it raised a TypeError because you cannot perform datetime arithmetic on mixed naive/aware datetimes.

## Solution Implemented

### 1. Fixed Datetime Usage
- **File**: `src/app/services/task_execution_service.py`
- **Change**: Replaced all `datetime.utcnow()` with `datetime.now(timezone.utc)`
- **Impact**: All timestamps created in task execution are now consistently timezone-aware

### 2. Added Defensive Duration Calculation
Added timezone-awareness checks before subtracting datetimes:
```python
# Ensure both timestamps are timezone-aware before subtraction
start = task_db.started_at if task_db.started_at.tzinfo else task_db.started_at.replace(tzinfo=timezone.utc)
end = task_db.completed_at if task_db.completed_at.tzinfo else task_db.completed_at.replace(tzinfo=timezone.utc)
task_db.actual_duration = (end - start).total_seconds()
```

This handles legacy data that might have naive timestamps.

### 3. Cleaned Legacy Data
- Cleared timezone error messages from 12 affected tasks
- Script: `clear_timezone_errors.py`

## Verification Results

### ‚úÖ Test Results
```bash
python test_datetime_fix.py
```
Output: "‚úÖ SUCCESS: No timezone error! Duration calculated correctly: 4.692167s"

### ‚úÖ New Tasks Working
- New analysis tasks complete successfully
- Results are saved and viewable
- Subtasks execute properly
- No timezone errors in new task execution

### ‚úÖ Analysis Results Now Display
Example from recent task:
- Total findings: 0
- Tools executed: 3
- Services count: 1
- Status: completed

## Files Changed
1. `src/app/services/task_execution_service.py` - Main fix
2. `docs/fixes/TIMEZONE_FIX_2025-10-26.md` - Documentation
3. Created helper scripts:
   - `test_datetime_fix.py` - Verification script
   - `clear_timezone_errors.py` - Legacy data cleanup
   - `check_results.py` - Results verification

## Impact
- **Before**: Analysis tasks failed with timezone errors, no results produced
- **After**: Analysis tasks execute successfully, results are saved and displayable

## Best Practices Going Forward
Always use timezone-aware datetimes in Python:
- ‚úÖ Use: `datetime.now(timezone.utc)`
- ‚ùå Avoid: `datetime.utcnow()` (deprecated in Python 3.12)

## Testing Instructions
To verify the fix:
```bash
# 1. Test new task execution
python test_datetime_fix.py

# 2. Check task results  
python check_results.py

# 3. Run debug analysis
python debug_analysis.py
```

## Status
üü¢ **RESOLVED** - Analysis tasks now execute successfully and produce viewable results.
